Workbook

Sheet 每日訓練紀錄
A1: 日期 | B1: 星期 | C1: 訓練類型 | D1: 訓練時長(分鐘) | E1: 阻力/轉數設定 | F1: 重量設定 | G1: 消耗熱量(卡) | H1: RPE自覺費力程度(0-10) | I1: 睡眠時數(前一晚) | J1: 睡眠品質自評(1-5) | K1: 壓力指數(1-5) | L1: 疲勞感(1-5) | M1: 自覺恢復程度(1-5) | N1: 達成當日目標(Y/N) | O1: 未達成原因 | P1: 心得備註
A2: 46273 | B2: =IF(A2="","",TEXT(A2,"aaa")) -> 週二 | C2: 飛輪 | D2: 30 | E2: 4 | F2: 3 | G2: 47 | H2: 6 | I2: 6.5 | J2: 3 | K2: 3 | L2: 3 | M2: 3 | N2: Y | O2: 不適用 | P2: 終於到貨，在家騎超方便，不用換衣服借鑰匙
A3: 46274 | B3: =IF(A3="","",TEXT(A3,"aaa")) -> 週三 | C3: 飛輪 | D3: 30 | E3: 3 | F3: 3 | G3: 47 | H3: 5 | I3: 7 | J3: 4 | K3: 2 | L3: 2 | M3: 4 | N3: Y | O3: 不適用 | P3: 把握7天鑑賞期，沒想到有異音，聯繫客服希望能得到解決．
A4: 46275 | B4: =IF(A4="","",TEXT(A4,"aaa")) -> 週四 | C4: 休息日 | D4: 0 | G4: 0 | I4: 6 | J4: 3 | K4: 4 | L4: 4 | M4: 3 | N4: N | O4: 工作忙 | P4: 上課回家很晚累了
A5: 46276 | B5: =IF(A5="","",TEXT(A5,"aaa")) -> 週五 | C5: 飛輪 | D5: 30 | E5: 3 | F5: 3 | G5: 47 | H5: 5 | I5: 6.5 | J5: 3 | K5: 3 | L5: 3 | M5: 3 | N5: Y | O5: 不適用
A6: 46277 | B6: =IF(A6="","",TEXT(A6,"aaa")) -> 週六 | C6: 飛輪 | D6: 30 | E6: 4 | F6: 3 | G6: 47 | H6: 7 | I6: 7.5 | J6: 4 | K6: 2 | L6: 3 | M6: 4 | N6: Y | O6: 不適用 | P6: 週末比較有時間，騎久一點
A7: 46278 | B7: =IF(A7="","",TEXT(A7,"aaa")) -> 週日 | C7: 休息日 | D7: 0 | G7: 0 | I7: 8 | J7: 4 | K7: 2 | L7: 2 | M7: 4 | N7: N | O7: 沒動力 | P7: 週日賴床，一直拖到後來懶得騎了
A8: 46279 | B8: =IF(A8="","",TEXT(A8,"aaa")) -> 週一 | C8: 飛輪 | D8: 30 | E8: 3 | F8: 3 | G8: 47 | H8: 4 | I8: 6.5 | J8: 3 | K8: 3 | L8: 3 | M8: 3 | N8: Y | O8: 不適用
A9: 46280 | B9: =IF(A9="","",TEXT(A9,"aaa")) -> 週二 | C9: 飛輪 | D9: 30 | E9: 4 | F9: 3 | G9: 47 | H9: 6 | I9: 6 | J9: 2 | K9: 4 | L9: 4 | M9: 2 | N9: Y | O9: 不適用 | P9: 有點累但還是騎完了
A10: 46281 | B10: =IF(A10="","",TEXT(A10,"aaa")) -> 週三 | C10: 休息日 | D10: 0 | G10: 0 | I10: 5.5 | J10: 2 | K10: 4 | L10: 5 | M10: 2 | N10: N | O10: 太累 | P10: 上課到很晚，回家只想洗洗睡
A11: 46282 | B11: =IF(A11="","",TEXT(A11,"aaa")) -> 週四 | C11: 飛輪 | D11: 30 | E11: 3 | F11: 3 | G11: 47 | H11: 5 | I11: 6.5 | J11: 3 | K11: 3 | L11: 3 | M11: 3 | N11: Y | O11: 不適用
A12: 46283 | B12: =IF(A12="","",TEXT(A12,"aaa")) -> 週五 | C12: 飛輪 | D12: 30 | E12: 3 | F12: 3 | G12: 47 | H12: 5 | I12: 7 | J12: 4 | K12: 2 | L12: 3 | M12: 4 | N12: Y | O12: 不適用
A13: 46284 | B13: =IF(A13="","",TEXT(A13,"aaa")) -> 週六 | C13: 飛輪 | D13: 30 | E13: 4 | F13: 3 | G13: 47 | H13: 7 | I13: 7.5 | J13: 4 | K13: 2 | L13: 3 | M13: 4 | N13: Y | O13: 不適用 | P13: 週末狀態不錯
A14: 46285 | B14: =IF(A14="","",TEXT(A14,"aaa")) -> 週日 | C14: 飛輪 | D14: 30 | E14: 3 | F14: 3 | G14: 47 | H14: 4 | I14: 7.5 | J14: 4 | K14: 2 | L14: 2 | M14: 5 | N14: Y | O14: 不適用 | P14: 邊上課 邊運動
A15: 46286 | B15: =IF(A15="","",TEXT(A15,"aaa")) -> 週一 | C15: 休息日 | D15: 0 | G15: 0 | I15: 6.5 | J15: 3 | K15: 4 | L15: 4 | M15: 3 | N15: N | O15: 沒動力 | P15: 沒有特別原因，就是不想騎
A16: 46287 | B16: =IF(A16="","",TEXT(A16,"aaa")) -> 週二 | C16: 飛輪 | D16: 30 | E16: 4 | F16: 3 | G16: 47 | H16: 6 | I16: 6.5 | J16: 3 | K16: 3 | L16: 3 | M16: 3 | N16: Y | O16: 不適用
A17: 46288 | B17: =IF(A17="","",TEXT(A17,"aaa")) -> 週三 | C17: 飛輪 | D17: 30 | E17: 3 | F17: 3 | G17: 47 | H17: 5 | I17: 7 | J17: 3 | K17: 3 | L17: 3 | M17: 4 | N17: Y | O17: 不適用 | P17: 今天狀態普通，照常騎完30分鐘
A18: 46289 | B18: =IF(A18="","",TEXT(A18,"aaa")) -> 週四 | C18: 休息日 | D18: 0 | G18: 0
A19: 46290 | B19: =IF(A19="","",TEXT(A19,"aaa")) -> 週五 | C19: 飛輪 | D19: 30 | F19: 3 | G19: 47
A20: 46291 | B20: =IF(A20="","",TEXT(A20,"aaa")) -> 週六 | C20: 飛輪 | D20: 30 | F20: 3 | G20: 47
A21: 46292 | B21: =IF(A21="","",TEXT(A21,"aaa")) -> 週日 | C21: 飛輪 | D21: 30 | F21: 3 | G21: 47
A22: 46293 | B22: =IF(A22="","",TEXT(A22,"aaa")) -> 週一 | C22: 休息日 | D22: 0 | G22: 0
A23: 46294 | B23: =IF(A23="","",TEXT(A23,"aaa")) -> 週二 | C23: 飛輪 | D23: 30 | F23: 3 | G23: 47
A24: 46295 | B24: =IF(A24="","",TEXT(A24,"aaa")) -> 週三 | C24: 休息日 | D24: 0 | G24: 0
A25: 46296 | B25: =IF(A25="","",TEXT(A25,"aaa")) -> 週四 | C25: 休息日 | D25: 0 | G25: 0
A26: 46297 | B26: =IF(A26="","",TEXT(A26,"aaa")) -> 週五 | C26: 飛輪 | D26: 30 | F26: 3 | G26: 47
A27: 46298 | B27: =IF(A27="","",TEXT(A27,"aaa")) -> 週六 | C27: 飛輪 | D27: 30 | F27: 3 | G27: 47
A28: 46299 | B28: =IF(A28="","",TEXT(A28,"aaa")) -> 週日 | C28: 飛輪 | D28: 30 | F28: 3 | G28: 47
A29: 46300 | B29: =IF(A29="","",TEXT(A29,"aaa")) -> 週一 | C29: 休息日 | D29: 0 | G29: 0
A30: 46301 | B30: =IF(A30="","",TEXT(A30,"aaa")) -> 週二 | C30: 飛輪 | D30: 30 | F30: 3 | G30: 47
A31: 46302 | B31: =IF(A31="","",TEXT(A31,"aaa")) -> 週三 | C31: 休息日 | D31: 0 | G31: 0
A32: 46303 | B32: =IF(A32="","",TEXT(A32,"aaa")) -> 週四 | C32: 休息日 | D32: 0 | G32: 0
A33: 46304 | B33: =IF(A33="","",TEXT(A33,"aaa")) -> 週五 | C33: 飛輪 | D33: 30 | F33: 3 | G33: 47
A34: 46305 | B34: =IF(A34="","",TEXT(A34,"aaa")) -> 週六 | C34: 飛輪 | D34: 30 | F34: 3 | G34: 47
A35: 46306 | B35: =IF(A35="","",TEXT(A35,"aaa")) -> 週日 | C35: 飛輪 | D35: 30 | F35: 3 | G35: 47
A36: 46307 | B36: =IF(A36="","",TEXT(A36,"aaa")) -> 週一 | C36: 休息日 | D36: 0 | G36: 0
A37: 46308 | B37: =IF(A37="","",TEXT(A37,"aaa")) -> 週二 | C37: 飛輪 | D37: 30 | F37: 3 | G37: 47
A38: 46309 | B38: =IF(A38="","",TEXT(A38,"aaa")) -> 週三 | C38: 休息日 | D38: 0 | G38: 0
A39: 46310 | B39: =IF(A39="","",TEXT(A39,"aaa")) -> 週四 | C39: 休息日 | D39: 0 | G39: 0
A40: 46311 | B40: =IF(A40="","",TEXT(A40,"aaa")) -> 週五 | C40: 飛輪 | D40: 30 | F40: 3 | G40: 47
...

Sheet 分析輔助
A1: 整體總覽
A2: 已記錄天數 | B2: =COUNTIF(每日訓練紀錄!A2:A95,"<="&TODAY()) -> 23
A3: 實際騎乘天數 | B3: =COUNTIF(每日訓練紀錄!N2:N95,"Y") -> 12
A4: 目標達成率 | B4: =IFERROR(COUNTIF(每日訓練紀錄!N2:N95,"Y")/COUNTIF(每日訓練紀錄!A2:A95,"<="&TODAY()),"") -> 0.52173913
A5: 平均RPE(騎乘日) | B5: =IFERROR(ROUND(AVERAGEIF(每日訓練紀錄!N2:N95,"Y",每日訓練紀錄!H2:H95),1),"") -> 5.4
A6: 平均睡眠時數 | B6: =IFERROR(ROUND(AVERAGE(每日訓練紀錄!I2:I95),1),"") -> 6.8
A7: 平均壓力指數 | B7: =IFERROR(ROUND(AVERAGE(每日訓練紀錄!K2:K95),1),"") -> 2.9
A8: 平均疲勞感 | B8: =IFERROR(ROUND(AVERAGE(每日訓練紀錄!L2:L95),1),"") -> 3.1
A9: 平均自覺恢復程度 | B9: =IFERROR(ROUND(AVERAGE(每日訓練紀錄!M2:M95),1),"") -> 3.4
A10: 累積消耗熱量(卡) | B10: =SUM(每日訓練紀錄!G2:G95) -> 2397
A11: 平均每次消耗熱量(騎乘日) | B11: =IFERROR(ROUND(AVERAGEIF(每日訓練紀錄!N2:N95,"Y",每日訓練紀錄!G2:G95),1),"") -> 47
A13: 交互影響：相關係數 (CORREL，介於 -1 ~ 1)
A14: 比較項目 | B14: 相關係數 | C14: 怎麼看
A15: RPE vs 睡眠時數 | B15: =IFERROR(ROUND(CORREL(每日訓練紀錄!H2:H95,每日訓練紀錄!I2:I95),2),"資料不足") -> 0.15 | C15: |係數|>0.5 通常算有明顯關聯，可作為魚骨圖／5Why的線索
A16: RPE vs 壓力指數 | B16: =IFERROR(ROUND(CORREL(每日訓練紀錄!H2:H95,每日訓練紀錄!K2:K95),2),"資料不足") -> -0.05 | C16: |係數|>0.5 通常算有明顯關聯，可作為魚骨圖／5Why的線索
A17: 自覺恢復程度 vs 睡眠時數 | B17: =IFERROR(ROUND(CORREL(每日訓練紀錄!M2:M95,每日訓練紀錄!I2:I95),2),"資料不足") -> 0.88 | C17: |係數|>0.5 通常算有明顯關聯，可作為魚骨圖／5Why的線索
A18: 自覺恢復程度 vs 壓力指數 | B18: =IFERROR(ROUND(CORREL(每日訓練紀錄!M2:M95,每日訓練紀錄!K2:K95),2),"資料不足") -> -0.85 | C18: |係數|>0.5 通常算有明顯關聯，可作為魚骨圖／5Why的線索
A20: 未達成原因統計 (柏拉圖用)
A21: 原因 | B21: 次數
A22: 時間不夠 | B22: =COUNTIF(每日訓練紀錄!O2:O95,"時間不夠") -> 0
A23: 太累 | B23: =COUNTIF(每日訓練紀錄!O2:O95,"太累") -> 1
A24: 工作忙 | B24: =COUNTIF(每日訓練紀錄!O2:O95,"工作忙") -> 1
A25: 沒動力 | B25: =COUNTIF(每日訓練紀錄!O2:O95,"沒動力") -> 2
A26: 身體不適 | B26: =COUNTIF(每日訓練紀錄!O2:O95,"身體不適") -> 0
A27: 其他 | B27: =COUNTIF(每日訓練紀錄!O2:O95,"其他") -> 0
A29: 註：目標達成率＝到今天為止「已騎飛輪(Y)」天數 ÷ 到今天為止「已記錄」天數(含休息日)，未來日期不會被算入分母，會隨日期自動往後展開。

Sheet 使用說明
A1: 居家飛輪運動改善主題 —— 追蹤表使用說明
A3: 這份表格對應 TQM 課程「個人改善主題 H1–H4」作業，記錄你在家騎飛輪的狀況。
A5: 【重要提醒：哪些數據是真的，哪些是示範】
A6: 日期、訓練類型(飛輪)、時長(30分鐘)、阻力設定(3-4)、重量設定(3)、消耗熱量(47卡)、是否達成(Y/N)、未達成原因、心得——這些是依照你給的真實資訊填入的。
A7: 但 RPE、睡眠時數、睡眠品質、壓力指數、疲勞感、自覺恢復程度 這幾欄（綠色底），是 AI 依你的騎乘天數草擬的示範數值，不是你真正量測的結果。請在提交作業前，對照自己實際的睡眠/壓力/體感狀況逐格修正——課程要求「資料自己量、分析自己做」，也需要在AI使用聲明中誠實說明這一點。
A9: 【使用方式】
A10: 1. 已經幫你填了9/8-9/23共16天的實際資料。第18-85列(9/24-11/30)已依你的課表(星期一、三、四上課不排運動，其他天排飛輪)預先排好日期與運動/休息類型，灰底=預排值(可覆蓋)，藍底=請當天實際發生後再填寫(睡眠/壓力/疲勞感/恢復程度/RPE/是否達成/原因/心得)，未發生的日期請不要提前填。第86列以後是完全空白列，12月以後要繼續用可自行往下複製格式延伸。
A11: 2. 「分析輔助」會自動算達成率、平均RPE、相關係數、未達成原因統計，還有兩張圖（熱量趨勢、原因次數）。
A13: 【欄位對照 H1–H4】
A14: H1：顧客可以是「未來的自己」或「希望你多運動的家人」；品質成本——預防（買飛輪車、設置空間，這筆錢本身就是預防投資）、鑑定（每天檢查有沒有騎）、內部失敗（因為太累臨時縮短時間）、外部失敗（沒達成運動目標、健康/心情沒改善）。
A15: H2：Run Chart 用「消耗熱量」或「是否達成(Y/N)」都可以，畫15-25天的趨勢，觀察是否越來越規律。
A16: H3：「未達成原因」欄位直接變成柏拉圖分類；魚骨圖可以拆「時間管理」「動力/心理」「環境/習慣」「身體狀況」幾個分支；5Why可以追問「為什麼今天沒騎」一路問到根本原因。
... A19: 提醒：依課程 AI 使用規範，作業末尾記得附上「AI 使用聲明與查證紀錄」，誠實說明表格中哪些數據是AI草擬示範、你實際查證修正了哪些地方。
